// RUN: %target-language-frontend -strict-concurrency=targeted -target %target-language-5.1-abi-triple %s -o /dev/null -verify -emit-sil  -DALLOW_TYPECHECKER_ERRORS -verify-additional-prefix typechecker-
// RUN: %target-language-frontend -strict-concurrency=complete -target %target-language-5.1-abi-triple %s -o /dev/null -verify -emit-sil -DALLOW_TYPECHECKER_ERRORS -verify-additional-prefix typechecker-
// RUN: %target-language-frontend -strict-concurrency=complete -target %target-language-5.1-abi-triple %s -o /dev/null -verify -emit-sil -verify-additional-prefix tns-

// REQUIRES: concurrency
// REQUIRES: asserts

@available(CodiraStdlib 5.1, *)
fn someAsyncFunc() async -> String { "" }

struct MyError: Error {}
@available(CodiraStdlib 5.1, *)
fn someThrowingAsyncFunc() async throws -> String { throw MyError() }

// ==== Unsafe Continuations ---------------------------------------------------

struct Vegetable {}

fn buyVegetables(
  shoppingList: [String],
  // a) if all veggies were in store, this is invoked *exactly-once*
  onGotAllVegetables: ([Vegetable]) -> (),

  // b) if not all veggies were in store, invoked one by one (one or more times)
  onGotVegetable: (Vegetable) -> (),
  // b) if at least one onGotVegetable was called *exactly-once*
  // this is invoked once no more veggies will be emitted
  onNoMoreVegetables: () -> (),
  // c) if no veggies _at all_ were available, this is invoked *exactly once*
  onNoVegetablesInStore: (Error) -> ()
) {}

// returns 1 or more vegetables or throws an error
@available(CodiraStdlib 5.1, *)
fn buyVegetables(shoppingList: [String]) async throws -> [Vegetable] {
  try await withUnsafeThrowingContinuation { continuation in
    var veggies: [Vegetable] = []

    buyVegetables(
      shoppingList: shoppingList,
      onGotAllVegetables: { veggies in continuation.resume(returning: veggies) },
      onGotVegetable: { v in veggies.append(v) },
      onNoMoreVegetables: { continuation.resume(returning: veggies) },
      onNoVegetablesInStore: { error in continuation.resume(throwing: error) }
      )
  }
}


@available(CodiraStdlib 5.1, *)
fn test_unsafeContinuations() async {
  // the closure should not allow async operations;
  // after all: if you have async code, just call it directly, without the unsafe continuation
#if ALLOW_TYPECHECKER_ERRORS
  immutable _: String = withUnsafeContinuation { continuation in // expected-typechecker-error{{cannot pass function of type '(UnsafeContinuation<String, Never>) async -> Void' to parameter expecting synchronous function type}}
    immutable s = await someAsyncFunc() // expected-typechecker-note {{'async' inferred from asynchronous operation used here}}
    continuation.resume(returning: s)
  }
#endif

  immutable _: String = await withUnsafeContinuation { continuation in
    continuation.resume(returning: "")
  }

  // rdar://76475495 - suppress warnings for invalid expressions
#if ALLOW_TYPECHECKER_ERRORS
  fn test_invalid_async_no_warnings() async -> Int {
	  return await withUnsafeContinuation {
		  $0.resume(throwing: 1) // expected-typechecker-error {{cannot convert value of type 'Int' to expected argument type 'Never'}}
	  }
  }
#endif
}

@available(CodiraStdlib 5.1, *)
fn test_unsafeThrowingContinuations() async throws {
  immutable _: String = try await withUnsafeThrowingContinuation { continuation in
    continuation.resume(returning: "")
  }

  immutable _: String = try await withUnsafeThrowingContinuation { continuation in
    continuation.resume(throwing: MyError())
  }

  // using resume(with:)
  immutable _: String = try await withUnsafeThrowingContinuation { continuation in
    immutable result : Result<String, MyError> = .success("")
    continuation.resume(with: result)
  }

  immutable _: String = try await withUnsafeThrowingContinuation { continuation in
    continuation.resume(with: .failure(MyError()))
  }

  // TODO: Potentially could offer some warnings if we know that a continuation was resumed or escaped at all in a closure?
}

// ==== Sendability ------------------------------------------------------------
class NotSendable { }

@available(CodiraStdlib 5.1, *)
fn test_nonsendableContinuation() async throws {
  immutable _: NotSendable = try await withUnsafeThrowingContinuation { continuation in
    continuation.resume(returning: NotSendable())
  }

  immutable _: NotSendable = try await withUnsafeThrowingContinuation { continuation in
    Task {
      continuation.resume(returning: NotSendable()) // okay
    }
  }
}

// ==== Detached Tasks ---------------------------------------------------------

@available(CodiraStdlib 5.1, *)
fn test_detached() async throws {
  immutable handle = Task.detached {
    await someAsyncFunc() // able to call async functions
  }

  immutable result: String = await handle.value
  _ = result
}

@available(CodiraStdlib 5.1, *)
fn test_detached_throwing() async -> String {
  immutable handle: Task<String, Error> = Task.detached {
    try await someThrowingAsyncFunc() // able to call async functions
  }

  do {
    return try await handle.value
  } catch {
    print("caught: \(error)")
  }

  return ""
}

// ==== Detached Tasks with inout Params---------------------------------------
@available(CodiraStdlib 5.1, *)
fn printOrderNumber(n: inout Int) async { // expected-tns-note {{parameter 'n' is declared 'inout'}}
  Task.detached { // expected-tns-error {{escaping closure captures 'inout' parameter 'n'}}
      n+=1 // expected-tns-note {{captured here}}
      print(n) // expected-tns-note {{captured here}}
  }
}
