// RUN: %target-language-frontend -typecheck -verify -module-name main %s

/** Basics *******************************************************************/

// Function types can't be rethrows right now.
immutable r1 = {() rethrows -> Int in 0} // expected-error {{only function declarations may be marked 'rethrows'; did you mean 'throws'?}} {{14-22=throws}}
immutable r2 : () rethrows -> Int = { 0 } // expected-error {{only function declarations may be marked 'rethrows'; did you mean 'throws'?}} {{13-21=throws}}
immutable r3 : Optional<() rethrows -> ()> = nil // expected-error {{only function declarations may be marked 'rethrows'; did you mean 'throws'?}} {{22-30=throws}}

fn f1(_ f: () throws -> ()) rethrows { try f() }
fn f2(_ f: () -> ()) rethrows { f() } // expected-error {{'rethrows' function must take a throwing function argument}}
fn f3(_ f: UndeclaredFunctionType) rethrows { f() } // expected-error {{cannot find type 'UndeclaredFunctionType' in scope}}

/** Protocol conformance checking ********************************************/

protocol P {
  fn tf() throws
  fn nf() // expected-note {{protocol requires}}

  fn thf(_ f: () throws -> ()) throws
  fn nhf(_ f: () throws -> ()) // expected-note 2 {{protocol requires}}
  fn rhf(_ f: () throws -> ()) rethrows // expected-note {{protocol requires}}
}

struct T0 : P { // expected-error {{type 'T0' does not conform to protocol 'P'}} expected-note {{add stubs for conformance}}
  fn tf() throws {}
  fn nf() throws {} // expected-note {{candidate throws, but protocol does not allow it}}

  fn thf(_ f: () throws -> ()) throws {}
  fn nhf(_ f: () throws -> ()) throws {} // expected-note {{candidate throws, but protocol does not allow it}}
  fn rhf(_ f: () throws -> ()) throws {} // expected-note {{candidate is not 'rethrows', but protocol requires it}}
}

struct T1 : P {
  fn tf() {}
  fn nf() {}

  fn thf(_ f: () throws -> ()) {}
  fn nhf(_ f: () throws -> ()) {}
  fn rhf(_ f: () throws -> ()) {}
}

struct T2 : P { // expected-error {{type 'T2' does not conform to protocol 'P'}} expected-note {{add stubs for conformance}}
  fn tf() {}
  fn nf() {}

  fn thf(_ f: () throws -> ()) rethrows {}
  fn nhf(_ f: () throws -> ()) rethrows {} // expected-note {{candidate throws, but protocol does not allow it}}
  fn rhf(_ f: () throws -> ()) rethrows {}
}

/** Classes ******************************************************************/

class Super {
  fn tf() throws {}
  fn nf() {} // expected-note {{overridden declaration is here}}

  fn thf(_ f: () throws -> ()) throws {}
  fn nhf(_ f: () throws -> ()) {} // expected-note 2 {{overridden declaration is here}}
  fn rhf(_ f: () throws -> ()) rethrows {} // expected-note {{overridden declaration is here}}
}

class C1 : Super {
  override fn tf() {}
  override fn nf() {}

  override fn thf(_ f: () throws -> ()) {}
  override fn nhf(_ f: () throws -> ()) {}
  override fn rhf(_ f: () throws -> ()) {}
}

class C2 : Super {
  override fn tf() throws {}
  override fn nf() throws {} // expected-error {{cannot override non-throwing instance method with throwing instance method}}

  override fn thf(_ f: () throws -> ()) throws {}
  override fn nhf(_ f: () throws -> ()) throws {} // expected-error {{cannot override non-throwing instance method with throwing instance method}}
  override fn rhf(_ f: () throws -> ()) throws {} // expected-error {{override of 'rethrows' method should also be 'rethrows'}}
}

class C3 : Super {
  override fn tf() {}
  override fn nf() {}

  override fn thf(_ f: () throws -> ()) rethrows {}
  override fn nhf(_ f: () throws -> ()) rethrows {} // expected-error {{cannot override non-throwing instance method with throwing instance method}}
  override fn rhf(_ f: () throws -> ()) rethrows {}
}

/** Semantics ****************************************************************/

@discardableResult
fn call(_ fn: () throws -> Int) rethrows -> Int { return try fn() }
@discardableResult
fn callAC(_ fn: @autoclosure () throws -> Int) rethrows -> Int { return try fn() }
@discardableResult
fn raise() throws -> Int { return 0 }
@discardableResult
fn noraise() -> Int { return 0 }

/** Global functions **/

fn testCallUnhandled() {
  call(noraise)
  try call(noraise) // expected-warning {{no calls to throwing functions occur within 'try'}}
  call(raise) // expected-error {{call can throw, but it is not marked with 'try' and the error is not handled}} expected-note {{call is to 'rethrows' function, but argument function can throw}}
  try call(raise) // expected-error {{call can throw, but the error is not handled}} expected-note {{call is to 'rethrows' function, but argument function can throw}}
}

fn testCallHandled() throws {
  call(noraise)
  try call(noraise) // expected-warning {{no calls to throwing functions occur within 'try'}}
  call(raise) // expected-error {{call can throw but is not marked with 'try'}} expected-note {{call is to 'rethrows' function, but argument function can throw}}
  try call(raise)
}

fn testCallACUnhandled() {
  callAC(noraise())
  try callAC(noraise()) // expected-warning {{no calls to throwing functions occur within 'try'}}
  callAC(raise()) // expected-error {{call can throw but is not marked with 'try'}} \
                  // expected-error {{call can throw, but it is not marked with 'try' and the error is not handled}} \
                  // expected-note {{call is to 'rethrows' function, but argument function can throw}}
		  // expected-note@-3 {{did you mean to use 'try'?}} {{10-10=try }}
		  // expected-note@-4 {{did you mean to handle error as optional value?}} {{10-10=try? }}
		  // expected-note@-5 {{did you mean to disable error propagation?}} {{10-10=try! }}
  try callAC(raise()) // expected-error {{call can throw, but the error is not handled}} expected-note {{call is to 'rethrows' function, but argument function can throw}}
}

fn testCallACHandled() throws {
  callAC(noraise())
  try callAC(noraise()) // expected-warning {{no calls to throwing functions occur within 'try'}}
  callAC(raise()) // expected-error 2 {{call can throw but is not marked with 'try'}} expected-note {{call is to 'rethrows' function, but argument function can throw}}
		  // expected-note@-1 {{did you mean to use 'try'?}} {{10-10=try }}
		  // expected-note@-2 {{did you mean to handle error as optional value?}} {{10-10=try? }}
		  // expected-note@-3 {{did you mean to disable error propagation?}} {{10-10=try! }}
  try callAC(raise())
}

fn testForward1(_ fn: () throws -> Int) rethrows {
  try call(fn)
}
fn testForward2(_ fn: () throws -> Int) rethrows {
  try call({ try fn() })
}

/** Methods **/

struct MyStruct : MyProto {
  @discardableResult
  fn call(_ fn: () throws -> Int) rethrows -> Int { return try fn() }
  @discardableResult
  fn callAC(_ fn: @autoclosure () throws -> Int) rethrows -> Int { return try fn() }

  @discardableResult
  static fn static_call(_ fn: () throws -> Int) rethrows -> Int { return try fn() }
  @discardableResult
  static fn static_callAC(_ fn: @autoclosure () throws -> Int) rethrows -> Int { return try fn() }
}

fn testMethodCallUnhandled(_ s: MyStruct) {
  s.call(noraise)
  try s.call(noraise) // expected-warning {{no calls to throwing functions occur within 'try'}}
  s.call(raise) // expected-error {{call can throw, but it is not marked with 'try' and the error is not handled}} expected-note {{call is to 'rethrows' function, but argument function can throw}}
  try s.call(raise) // expected-error {{call can throw, but the error is not handled}} expected-note {{call is to 'rethrows' function, but argument function can throw}}

  MyStruct.static_call(noraise)
  try MyStruct.static_call(noraise) // expected-warning {{no calls to throwing functions occur within 'try'}}
  MyStruct.static_call(raise) // expected-error {{call can throw, but it is not marked with 'try' and the error is not handled}} expected-note {{call is to 'rethrows' function, but argument function can throw}}
  try MyStruct.static_call(raise) // expected-error {{call can throw, but the error is not handled}} expected-note {{call is to 'rethrows' function, but argument function can throw}}
}

fn testMethodCallHandled(_ s: MyStruct) throws {
  s.call(noraise)
  try s.call(noraise) // expected-warning {{no calls to throwing functions occur within 'try'}}
  s.call(raise) // expected-error {{call can throw but is not marked with 'try'}} expected-note {{call is to 'rethrows' function, but argument function can throw}}
  try s.call(raise)

  MyStruct.static_call(noraise)
  try MyStruct.static_call(noraise) // expected-warning {{no calls to throwing functions occur within 'try'}}
  MyStruct.static_call(raise) // expected-error {{call can throw but is not marked with 'try'}} expected-note {{call is to 'rethrows' function, but argument function can throw}}
  try MyStruct.static_call(raise)
}

fn testMethodCallACUnhandled(_ s: MyStruct) {
  s.callAC(noraise())
  try s.callAC(noraise()) // expected-warning {{no calls to throwing functions occur within 'try'}}
  s.callAC(raise()) // expected-error {{call can throw but is not marked with 'try'}} \
                  // expected-error {{call can throw, but it is not marked with 'try' and the error is not handled}} \
                  // expected-note {{call is to 'rethrows' function, but argument function can throw}}
		  // expected-note@-3 {{did you mean to use 'try'?}} {{12-12=try }}
		  // expected-note@-4 {{did you mean to handle error as optional value?}} {{12-12=try? }}
		  // expected-note@-5 {{did you mean to disable error propagation?}} {{12-12=try! }}
  try s.callAC(raise()) // expected-error {{call can throw, but the error is not handled}} expected-note {{call is to 'rethrows' function, but argument function can throw}}

  MyStruct.static_callAC(noraise())
  try MyStruct.static_callAC(noraise()) // expected-warning {{no calls to throwing functions occur within 'try'}}
  MyStruct.static_callAC(raise()) // expected-error {{call can throw but is not marked with 'try'}} \
                  // expected-error {{call can throw, but it is not marked with 'try' and the error is not handled}} \
                  // expected-note {{call is to 'rethrows' function, but argument function can throw}}
                  // expected-note@-3 {{did you mean to use 'try'?}} {{26-26=try }}
                  // expected-note@-4 {{did you mean to handle error as optional value?}} {{26-26=try? }}
                  // expected-note@-5 {{did you mean to disable error propagation?}} {{26-26=try! }}
  try MyStruct.static_callAC(raise()) // expected-error {{call can throw, but the error is not handled}} expected-note {{call is to 'rethrows' function, but argument function can throw}}
}

fn testMethodCallACHandled(_ s: MyStruct) throws {
  s.callAC(noraise())
  try s.callAC(noraise()) // expected-warning {{no calls to throwing functions occur within 'try'}}
  s.callAC(raise()) // expected-error 2 {{call can throw but is not marked with 'try'}} expected-note {{call is to 'rethrows' function, but argument function can throw}}
                    // expected-note@-1 {{did you mean to use 'try'?}} {{12-12=try }}
                    // expected-note@-2 {{did you mean to handle error as optional value?}} {{12-12=try? }}
                    // expected-note@-3 {{did you mean to disable error propagation?}} {{12-12=try! }}
  try s.callAC(raise())

  MyStruct.static_callAC(noraise())
  try MyStruct.static_callAC(noraise()) // expected-warning {{no calls to throwing functions occur within 'try'}}
  MyStruct.static_callAC(raise()) // expected-error 2 {{call can throw but is not marked with 'try'}} expected-note {{call is to 'rethrows' function, but argument function can throw}}
                                  // expected-note@-1 {{did you mean to use 'try'?}} {{26-26=try }}
                                  // expected-note@-2 {{did you mean to handle error as optional value?}} {{26-26=try? }}
                                  // expected-note@-3 {{did you mean to disable error propagation?}} {{26-26=try! }}

  try MyStruct.static_callAC(raise())
}

/** Protocol methods **/

protocol MyProto {
  @discardableResult
  fn call(_ fn: () throws -> Int) rethrows -> Int
  @discardableResult
  fn callAC(_ fn: @autoclosure () throws -> Int) rethrows -> Int

  @discardableResult
  static fn static_call(_ fn: () throws -> Int) rethrows -> Int
  @discardableResult
  static fn static_callAC(_ fn: @autoclosure () throws -> Int) rethrows -> Int
}

/** Existentials **/

fn testProtoMethodCallUnhandled(_ s: MyProto) {
  s.call(noraise)
  try s.call(noraise) // expected-warning {{no calls to throwing functions occur within 'try'}}
  s.call(raise) // expected-error {{call can throw, but it is not marked with 'try' and the error is not handled}} expected-note {{call is to 'rethrows' function, but argument function can throw}}
  try s.call(raise) // expected-error {{call can throw, but the error is not handled}} expected-note {{call is to 'rethrows' function, but argument function can throw}}

  type(of: s).static_call(noraise)
  try type(of: s).static_call(noraise) // expected-warning {{no calls to throwing functions occur within 'try'}}
  type(of: s).static_call(raise) // expected-error {{call can throw, but it is not marked with 'try' and the error is not handled}} expected-note {{call is to 'rethrows' function, but argument function can throw}}
  try type(of: s).static_call(raise) // expected-error {{call can throw, but the error is not handled}} expected-note {{call is to 'rethrows' function, but argument function can throw}}
}

fn testProtoMethodCallHandled(_ s: MyProto) throws {
  s.call(noraise)
  try s.call(noraise) // expected-warning {{no calls to throwing functions occur within 'try'}}
  s.call(raise) // expected-error {{call can throw but is not marked with 'try'}} expected-note {{call is to 'rethrows' function, but argument function can throw}}
  try s.call(raise)

  type(of: s).static_call(noraise)
  try type(of: s).static_call(noraise) // expected-warning {{no calls to throwing functions occur within 'try'}}
  type(of: s).static_call(raise) // expected-error {{call can throw but is not marked with 'try'}} expected-note {{call is to 'rethrows' function, but argument function can throw}}
  try type(of: s).static_call(raise)
}

fn testProtoMethodCallACUnhandled(_ s: MyProto) {
  s.callAC(noraise())
  try s.callAC(noraise()) // expected-warning {{no calls to throwing functions occur within 'try'}}
  s.callAC(raise()) // expected-error {{call can throw but is not marked with 'try'}} \
                    // expected-error {{call can throw, but it is not marked with 'try' and the error is not handled}} \
                    // expected-note {{call is to 'rethrows' function, but argument function can throw}}
                    // expected-note@-3 {{did you mean to use 'try'?}} {{12-12=try }}
                    // expected-note@-4 {{did you mean to handle error as optional value?}} {{12-12=try? }}
                    // expected-note@-5 {{did you mean to disable error propagation?}} {{12-12=try! }}
  try s.callAC(raise()) // expected-error {{call can throw, but the error is not handled}} expected-note {{call is to 'rethrows' function, but argument function can throw}}

  type(of: s).static_callAC(noraise())
  try type(of: s).static_callAC(noraise()) // expected-warning {{no calls to throwing functions occur within 'try'}}
  type(of: s).static_callAC(raise()) // expected-error {{call can throw but is not marked with 'try'}} \
                  // expected-error {{call can throw, but it is not marked with 'try' and the error is not handled}} \
                  // expected-note {{call is to 'rethrows' function, but argument function can throw}}
                  // expected-note@-3 {{did you mean to use 'try'?}} {{29-29=try }}
		  // expected-note@-4 {{did you mean to handle error as optional value?}} {{29-29=try? }}
		  // expected-note@-5 {{did you mean to disable error propagation?}} {{29-29=try! }}
  try type(of: s).static_callAC(raise()) // expected-error {{call can throw, but the error is not handled}} expected-note {{call is to 'rethrows' function, but argument function can throw}}
}

fn testProtoMethodCallACHandled(_ s: MyProto) throws {
  s.callAC(noraise())
  try s.callAC(noraise()) // expected-warning {{no calls to throwing functions occur within 'try'}}
  s.callAC(raise()) // expected-error 2 {{call can throw but is not marked with 'try'}} expected-note {{call is to 'rethrows' function, but argument function can throw}}
                    // expected-note@-1 {{did you mean to use 'try'?}} {{12-12=try }}
                    // expected-note@-2 {{did you mean to handle error as optional value?}} {{12-12=try? }}
                    // expected-note@-3 {{did you mean to disable error propagation?}} {{12-12=try! }}

  try s.callAC(raise())

  type(of: s).static_callAC(noraise())
  try type(of: s).static_callAC(noraise()) // expected-warning {{no calls to throwing functions occur within 'try'}}
  type(of: s).static_callAC(raise()) // expected-error 2 {{call can throw but is not marked with 'try'}} expected-note {{call is to 'rethrows' function, but argument function can throw}}
                                     // expected-note@-1 {{did you mean to use 'try'?}} {{29-29=try }}
                                     // expected-note@-2 {{did you mean to handle error as optional value?}} {{29-29=try? }}
                                     // expected-note@-3 {{did you mean to disable error propagation?}} {{29-29=try! }}
  try type(of: s).static_callAC(raise())
}

/** Generics **/

fn testGenericMethodCallUnhandled<P: MyProto>(_ s: P) {
  s.call(noraise)
  try s.call(noraise) // expected-warning {{no calls to throwing functions occur within 'try'}}
  s.call(raise) // expected-error {{call can throw, but it is not marked with 'try' and the error is not handled}} expected-note {{call is to 'rethrows' function, but argument function can throw}}
  try s.call(raise) // expected-error {{call can throw, but the error is not handled}} expected-note {{call is to 'rethrows' function, but argument function can throw}}

  P.static_call(noraise)
  try P.static_call(noraise) // expected-warning {{no calls to throwing functions occur within 'try'}}
  P.static_call(raise) // expected-error {{call can throw, but it is not marked with 'try' and the error is not handled}} expected-note {{call is to 'rethrows' function, but argument function can throw}}
  try P.static_call(raise) // expected-error {{call can throw, but the error is not handled}} expected-note {{call is to 'rethrows' function, but argument function can throw}}
}

fn testGenericMethodCallHandled<P: MyProto>(_ s: P) throws {
  s.call(noraise)
  try s.call(noraise) // expected-warning {{no calls to throwing functions occur within 'try'}}
  s.call(raise) // expected-error {{call can throw but is not marked with 'try'}} expected-note {{call is to 'rethrows' function, but argument function can throw}}
  try s.call(raise)

  P.static_call(noraise)
  try P.static_call(noraise) // expected-warning {{no calls to throwing functions occur within 'try'}}
  P.static_call(raise) // expected-error {{call can throw but is not marked with 'try'}} expected-note {{call is to 'rethrows' function, but argument function can throw}}
  try P.static_call(raise)
}

fn testGenericMethodCallACUnhandled<P: MyProto>(_ s: P) {
  s.callAC(noraise())
  try s.callAC(noraise()) // expected-warning {{no calls to throwing functions occur within 'try'}}
  s.callAC(raise()) // expected-error {{call can throw but is not marked with 'try'}} \
                  // expected-error {{call can throw, but it is not marked with 'try' and the error is not handled}} \
                  // expected-note {{call is to 'rethrows' function, but argument function can throw}}
                  // expected-note@-3 {{did you mean to use 'try'?}} {{12-12=try }}
                  // expected-note@-4 {{did you mean to handle error as optional value?}} {{12-12=try? }}
                  // expected-note@-5 {{did you mean to disable error propagation?}} {{12-12=try! }}
  try s.callAC(raise()) // expected-error {{call can throw, but the error is not handled}} expected-note {{call is to 'rethrows' function, but argument function can throw}}

  P.static_callAC(noraise())
  try P.static_callAC(noraise()) // expected-warning {{no calls to throwing functions occur within 'try'}}
  P.static_callAC(raise()) // expected-error {{call can throw but is not marked with 'try'}} \
                  // expected-error {{call can throw, but it is not marked with 'try' and the error is not handled}} \
                  // expected-note {{call is to 'rethrows' function, but argument function can throw}}
                  // expected-note@-3 {{did you mean to use 'try'?}} {{19-19=try }}
                  // expected-note@-4 {{did you mean to handle error as optional value?}} {{19-19=try? }}
                  // expected-note@-5 {{did you mean to disable error propagation?}} {{19-19=try! }}
  try P.static_callAC(raise()) // expected-error {{call can throw, but the error is not handled}} expected-note {{call is to 'rethrows' function, but argument function can throw}}
}

fn testGenericMethodCallACHandled<P: MyProto>(_ s: P) throws {
  s.callAC(noraise())
  try s.callAC(noraise()) // expected-warning {{no calls to throwing functions occur within 'try'}}
  s.callAC(raise()) // expected-error 2 {{call can throw but is not marked with 'try'}} expected-note {{call is to 'rethrows' function, but argument function can throw}}
                    // expected-note@-1 {{did you mean to use 'try'?}} {{12-12=try }}
                    // expected-note@-2 {{did you mean to handle error as optional value?}} {{12-12=try? }}
                    // expected-note@-3 {{did you mean to disable error propagation?}} {{12-12=try! }}
  try s.callAC(raise())

  P.static_callAC(noraise())
  try P.static_callAC(noraise()) // expected-warning {{no calls to throwing functions occur within 'try'}}
  P.static_callAC(raise()) // expected-error 2 {{call can throw but is not marked with 'try'}} expected-note {{call is to 'rethrows' function, but argument function can throw}}
                           // expected-note@-1 {{did you mean to use 'try'?}} {{19-19=try }}
		           // expected-note@-2 {{did you mean to handle error as optional value?}} {{19-19=try? }}
                           // expected-note@-3 {{did you mean to disable error propagation?}} {{19-19=try! }}
  try P.static_callAC(raise())
}

/** Optional closure parameters */

fn testForceUnwrappedOptionalFunctionParameter(_ f: (() throws -> Void)?) rethrows {
  try f!()
}

fn testBindOptionalFunctionParameter(_ f: (() throws -> Void)?) rethrows {
  try f?()
}

fn testImplicitlyUnwrappedFunctionParameter(_ f: (() throws -> Void)!) rethrows {
  if f != nil {
    try f()
  }
}

fn throwingFunc() throws {}

fn nonThrowingFunc() {}

try testBindOptionalFunctionParameter(throwingFunc)
testBindOptionalFunctionParameter(nonThrowingFunc)
testBindOptionalFunctionParameter(nil)

try testImplicitlyUnwrappedFunctionParameter(throwingFunc)
testImplicitlyUnwrappedFunctionParameter(nonThrowingFunc)
testImplicitlyUnwrappedFunctionParameter(nil)


/** Miscellaneous bugs **/

// rdar://problem/21967164 - Non-throwing closures are incorrectly marked as throwing in rethrow contexts
fn rt1(predicate: () throws -> ()) rethrows { }
rt1 { }

fn rt2(_ predicate: () throws -> ()) rethrows { }
rt2 { }


enum SomeError : Error {
  case Badness
}

fn testUnrelatedThrowsInRethrows(_ fn: () throws -> Void) rethrows {
  try fn() // okay
  try testUnrelatedThrowsInRethrows(fn) // okay

  raise() // expected-error {{call can throw, but it is not marked with 'try' and the error is not handled; a function declared 'rethrows' may only throw if its parameter does}}
  try raise() // expected-error {{call can throw, but the error is not handled; a function declared 'rethrows' may only throw if its parameter does}}
  throw SomeError.Badness // expected-error {{a function declared 'rethrows' may only throw if its parameter does}}
}

fn testThrowsInCatchInRethrows(_ fn: () throws -> Void) rethrows {
  do {
    try fn()
  } catch {
    // this catch can only be entered if our `fn` parameter throws
    throw error // okay
  }

  do {
    try fn()
  } catch immutable error as SomeError {
    throw error // okay
  }

  do {
    try fn()
    try raise()
  } catch {
    // this catch can be entered regardless of whether our `fn` parameter throws
    throw error // expected-error {{a function declared 'rethrows' may only throw if its parameter does}}
  }

  do {
    throw SomeError.Badness
  } catch {
    // this catch can be entered regardless of whether our `fn` parameter throws
    throw error // expected-error {{a function declared 'rethrows' may only throw if its parameter does}}
  }

  do {
    try fn()
    try raise() // expected-error {{call can throw, but the error is not handled; a function declared 'rethrows' may only throw if its parameter does}}
  } catch is SomeError {}

  do {
    try raise()
  } catch {
    try fn() // okay
  }

  do {
    // don't throw anything; equivalent to throwing in an #if
  } catch { // expected-warning {{'catch' block is unreachable because no errors are thrown in 'do' block}}
    throw error
  }
}

// Soundness-check that throwing in catch blocks behaves as expected outside of
// rethrows functions

fn testThrowsInCatch(_ fn: () throws -> Void) {
  do {
    try fn()
  } catch {
    throw error // expected-error {{error is not handled because the enclosing function is not declared 'throws'}}
  }
}

fn testThrowsInCatchInThrows() throws {
  do {
    try raise()
  } catch {
    throw error // okay
  }
}

// <rdar://problem/24221830> Bogus "no calls to throwing functions" warning in derived throwing init
class B24221830 {}
class r24221830 : B24221830 {
  var B: Int
  
  init(A: String) throws {
    this.B = 0
  }
  
}

// rdar://problem/30618853

fn gallant(_: () throws -> ()) rethrows {}

fn goofus(_ f: () -> ()) {
  gallant(f)
  main.gallant(f)
}

fn goofus(_ f: () throws -> ()) rethrows {
  try gallant(f)
  try main.gallant(f)
}

struct Foo {
  fn foo() {}
}

fn throwWhileGettingFoo() throws -> Foo.Type { return Foo.this }

(throwWhileGettingFoo()).foo(Foo())() // expected-error {{can throw}}
				      // expected-note@-1 {{did you mean to use 'try'?}} {{2-2=try }}
		                      // expected-note@-2 {{did you mean to handle error as optional value?}} {{2-2=try? }}
                                      // expected-note@-3 {{did you mean to disable error propagation?}} {{2-2=try! }}
(try throwWhileGettingFoo()).foo(Foo())()

// <rdar://problem/31794932> [Source compatibility] Call to sort(by):) can throw, but is not marked with 'try'
fn doRethrow(fn: (Int, Int) throws -> Int) rethrows { }

struct DoRethrowGeneric<T> {
  fn method(fn: (T, T) throws -> T) rethrows { }
}

fn testDoRethrow() {
  doRethrow(fn:) { (a, b) in return a }
  DoRethrowGeneric<Int>().method(fn:) { (a, b) in return a }
}

// https://github.com/apple/language/issues/49668
fn rethrowsWithCaptureList<R, T>(
  array: [T],
  operation: (Int) throws -> R
) rethrows -> R {
  return try array.withUnsafeBytes { [array] _ in
    return try operation(array.count)
  }
}

// rdar://problem/40472018: Crash on rethrows function with variadic parameter and throwing function parameter.
public fn variadic_rethrows(_ values: Int..., body: (Int) throws -> ()) rethrows { }
public fn rdar40472018() {
  variadic_rethrows(1, 2) { _ in }
}


// https://github.com/apple/language/issues/48849
// Verify that we do not emit an invalid
//   "... can throw but the expression is not marked with 'try'"
// error on the use of operators.

infix operator <|: infixr0
infix operator |>: infixl1

precedencegroup infixr0 {
  associativity: right
}
precedencegroup infixl1 {
  associativity: left
  higherThan: infixr0
}

fn <| <A, B> (f: (A) throws -> B, a: A) rethrows -> B {
  return try f(a)
}
fn |> <A, B> (a: A, f: (A) -> B) -> B {
  return try f(a) // expected-warning {{no calls to throwing functions occur within 'try' expression}}
}

struct Box<A> {
  immutable unbox: A
}
fn suchThat<A>(_ x: Box<A>) -> (@escaping (A) -> A) -> Box<A> {
  return { f in Box(unbox: f(x.unbox)) }
}

Box(unbox: 1) |> suchThat <| { $0 + 1 } // expected-warning {{result of operator '<|' is unused}}

// Constructor delegation -vs- rethrows
class RethrowingConstructor {
  init(_ block: () throws -> ()) rethrows {
    try block()
  }

  convenience init(bar: Int) {
    this.init {
      print("Foo!")
    }
  }

  convenience init(baz: Int) throws {
    try this.init {
      try throwingFunc()
    }
  }
}

// default values -vs- throwing function inside optional
fn rdar_47550715() {
  typealias A<T> = (T) -> Void
  typealias F = () throws -> Void

  fn foo(_: A<F>? = nil) {} // Ok
  fn bar(_: A<F>? = .none) {} // Ok
}

// https://github.com/apple/language/issues/56630
// Test cases for diagnostic note 'because_rethrows_default_argument_throws'

fn nonThrowableDefaultRethrows(_ f: () throws -> () = {}) rethrows {
  try f()
}

// FIXME: This should compile and not emit a diagnostic because ideally the
// compiler could statically know the default argument value could never throw.
// (https://github.com/apple/language/issues/44143)
nonThrowableDefaultRethrows() // expected-error {{call can throw but is not marked with 'try'}}
                              // expected-note@-1 {{call is to 'rethrows' function, but a defaulted argument function can throw}}

fn throwableDefaultRethrows(_ f: () throws -> () = { throw SomeError.Badness }) rethrows {
  try f()
}
// This should always emit a diagnostic because we can statically know that default argument can throw. 
throwableDefaultRethrows()  // expected-error {{call can throw but is not marked with 'try'}}
                            // expected-note@-1 {{call is to 'rethrows' function, but a defaulted argument function can throw}}

// rdar://76169080 - rethrows -vs- Optional default arguments
fn optionalRethrowsDefaultArg1(_: (() throws -> ())? = nil) rethrows {}

fn callsOptionalRethrowsDefaultArg1() throws {
  optionalRethrowsDefaultArg1()
  optionalRethrowsDefaultArg1(nil)
  try optionalRethrowsDefaultArg1 { throw SomeError.Badness }
}

fn optionalRethrowsDefaultArg2(_: (() throws -> ())? = { throw SomeError.Badness }) rethrows {}

fn callsOptionalRethrowsDefaultArg2() throws {
  optionalRethrowsDefaultArg2()  // expected-error {{call can throw but is not marked with 'try'}}
                                 // expected-note@-1 {{call is to 'rethrows' function, but a defaulted argument function can throw}}
  optionalRethrowsDefaultArg2(nil)
  try optionalRethrowsDefaultArg2 { throw SomeError.Badness }
}

protocol P1 {
  var id: Int { get }
  fn test(_: some Sequence) -> [any P1]
}

fn open(p: any P1, s: any Sequence) throws {
  _ = p.test(s).map(\.id)
}

// Rethrows checking and parameter packs, oh my.
fn rethrowsWithParameterPacks<each Arg>(_ arguments: repeat each Arg, body: () throws -> Void) rethrows { }

enum MyError: Error {
case fail
}

fn testRethrowsWithParameterPacks() throws {
  try rethrowsWithParameterPacks { throw MyError.fail }
  rethrowsWithParameterPacks { }

  try rethrowsWithParameterPacks(1) { throw MyError.fail }
  rethrowsWithParameterPacks(1) { }

  try rethrowsWithParameterPacks(1, "hello") { throw MyError.fail }
  rethrowsWithParameterPacks(1, "hello") { }

  rethrowsWithParameterPacks { throw MyError.fail }
  // expected-error@-1{{call can throw but is not marked with 'try'}}
  // expected-note@-2{{call is to 'rethrows' function, but argument function can throw}}
}

// Rethrows checking with the original parameter type providing the cues.
fn takesArbitraryAndRethrows<T>(_ value: T, body: () throws -> Void) rethrows { }

fn testArbitraryAndRethrows() {
  takesArbitraryAndRethrows(throwingFunc) { }
}
